Workbook

Sheet Бүх машин
A1: JP Auction → Монголд буух үнэ ба үнэлгээ | H1: Шинэчилсэн: 2026-10-06 · Загвар: model_2026-10-04_v6_2026fresh.json
A2: Иен ханш, ₮ | D2: Машин бүрт нэмэх, ¥ | F2: Ачилт тээвэр, ₮ | H2: НӨАТ | L2: Насыг тооцох он
A3: 22.93 | B3: ← засаж болно (2026-10-06, Голомт банк, JPY бэлэн бус зарах ханш (ikon.mn/xrates)) | D3: 100000 | F3: 2768000 | H3: 0.155 | L3: 2026
A4: Шар нүдийг өөрчлөхөд бүх буух үнэ, ашиг дахин бодогдоно. 'Нэмэх, ¥ (гараар)' баганад машин тус бүрийн дүнг оруулж болно (хоосон бол дээрх үндсэн дүн).
A5: Хаагдах цаг | B5: Аукцион | C5: Лот | D5: Загвар | E5: Код | F5: Комплектац | G5: Он | H5: Гүйлт, км | I5: cc | J5: Төрөл | K5: Оноо | L5: Өнгө | M5: Төлөв | N5: Миний үнэ, ¥ | O5: Эцсийн үнэ, ¥ | P5: Нэмэх, ¥ (гараар) | Q5: Нас | R5: Онцгой татвар, ₮ | S5: Буух үнэ (миний үнээр), ₮ | T5: Буух үнэ (эцсийн үнээр), ₮ | U5: Монголд зарагдах үнэ (загвар), ₮ | V5: Доод (25%), ₮ | W5: Дээд (75%), ₮ | X5: Ашиг (миний үнээр), ₮ | Y5: Ашгийн хувь | Z5: Ашиг (эцсийн үнээр), ₮ | AA5: Загварын итгэл | AB5: Загварт тооцсон шинж | AC5: Нэмэгдсэн | AD5: Тэмдэглэл | AE5: Түлхүүр
A6: 2026/10/07 14:06 | B6: CAA Chubu | C6: 11043 | D6: Prius Alpha | E6: ZVW41W | F6: G TOURING SELECTION | G6: 2012 | H6: 152000 | I6: 1800 | J6: Хайбрид | K6: 3.5 | L6: мөнгөлөг | M6: Хүлээгдэж буй - тэргүүлж байна | N6: 300000 | Q6: =$L$3-G6 -> 14 | R6: =IF(J6="Хайбрид",INDEX('Онцгой татвар'!$C$6:$F$10,MATCH(I6,'Онцгой татвар'!$B$6:$B$10,1),MATCH(Q6,'Онцгой татвар'!$C$5:$F$5,1)),INDEX('Онцгой татвар'!$C$15:$F$19,MATCH(I6,'Онцгой татвар'!$B$15:$B$19,1),MATCH(Q6,'Онцгой татвар'!$C$14:$F$14,1))) -> 5850000 | S6: =IF(N6="","",((N6+IF(P6="",$D$3,P6))*$A$3+$F$3+R6)*(1+$H$3)) -> 20547450 | T6: =IF(O6="","",((O6+IF(P6="",$D$3,P6))*$A$3+$F$3+R6)*(1+$H$3)) | U6: 26763000 | V6: 25663000 | W6: 27828000 | X6: =IF(OR(U6="",S6=""),"",U6-S6) -> 6215550 | Y6: =IF(X6="","",X6/S6) -> 0.30249739 | Z6: =IF(OR(U6="",T6=""),"",U6-T6) | AA6: Найдвартай (47 зар) | AB6: гүйлт 152k -0.1%, G Touring +3.2%, өнгө +7.1%, оноо 3.5 -1.2% | AC6: 2026-10-06 | AE6: CAA Chubu|11043|2026/10/07
A7: 2026/10/07 14:00 | C7: 19698 | D7: Camry | E7: AXVH70 | F7: 2WD | G7: 2017 | H7: 133000 | I7: 2500 | J7: Хайбрид | K7: 3.5 | L7: Mileage | M7: Хүлээгдэж буй - тэргүүлж байна | N7: 950000 | Q7: =$L$3-G7 -> 9 | R7: =IF(J7="Хайбрид",INDEX('Онцгой татвар'!$C$6:$F$10,MATCH(I7,'Онцгой татвар'!$B$6:$B$10,1),MATCH(Q7,'Онцгой татвар'!$C$5:$F$5,1)),INDEX('Онцгой татвар'!$C$15:$F$19,MATCH(I7,'Онцгой татвар'!$B$15:$B$19,1),MATCH(Q7,'Онцгой татвар'!$C$14:$F$14,1))) -> 2500000 | S7: =IF(N7="","",((N7+IF(P7="",$D$3,P7))*$A$3+$F$3+R7)*(1+$H$3)) -> 33892898 | T7: =IF(O7="","",((O7+IF(P7="",$D$3,P7))*$A$3+$F$3+R7)*(1+$H$3)) | U7: 47712000 | V7: 45749000 | W7: 49609000 | X7: =IF(OR(U7="",S7=""),"",U7-S7) -> 13819102 | Y7: =IF(X7="","",X7/S7) -> 0.40772857 | Z7: =IF(OR(U7="",T7=""),"",U7-T7) | AA7: Дунд (15 зар) | AB7: гүйлт 133k +0.4%, тодорхойгүй +2.4%, өнгө +7.1%, оноо 3.5 -1.2% | AC7: 2026-10-06 | AE7: |19698|2026/10/07
A8: 2026/10/07 13:44 | B8: CAA Chubu | C8: 30653 | D8: Prius Alpha | E8: ZVW41W | F8: G | G8: 2013 | H8: 142000 | I8: 1800 | J8: Хайбрид | K8: R | L8: сувдан цагаан | M8: Хүлээгдэж буй - тэргүүлж байна | N8: 300000 | Q8: =$L$3-G8 -> 13 | R8: =IF(J8="Хайбрид",INDEX('Онцгой татвар'!$C$6:$F$10,MATCH(I8,'Онцгой татвар'!$B$6:$B$10,1),MATCH(Q8,'Онцгой татвар'!$C$5:$F$5,1)),INDEX('Онцгой татвар'!$C$15:$F$19,MATCH(I8,'Онцгой татвар'!$B$15:$B$19,1),MATCH(Q8,'Онцгой татвар'!$C$14:$F$14,1))) -> 5850000 | S8: =IF(N8="","",((N8+IF(P8="",$D$3,P8))*$A$3+$F$3+R8)*(1+$H$3)) -> 20547450 | T8: =IF(O8="","",((O8+IF(P8="",$D$3,P8))*$A$3+$F$3+R8)*(1+$H$3)) | U8: 27310000 | V8: 26187000 | W8: 28397000 | X8: =IF(OR(U8="",S8=""),"",U8-S8) -> 6762550 | Y8: =IF(X8="","",X8/S8) -> 0.3291187 | Z8: =IF(OR(U8="",T8=""),"",U8-T8) | AA8: Найдвартай (40 зар) | AB8: гүйлт 142k +0.2%, G +1.1%, өнгө +6.1% | AC8: 2026-10-06 | AE8: CAA Chubu|30653|2026/10/07
A9: 2026/10/07 12:06 | B9: CAA Chubu | C9: 30344 | D9: Camry | E9: AXVH70 | F9: G | G9: 2018 | H9: 114000 | I9: 2500 | J9: Хайбрид | K9: R | L9: улаан | M9: Хүлээгдэж буй - тэргүүлж байна | N9: 950000 | Q9: =$L$3-G9 -> 8 | R9: =IF(J9="Хайбрид",INDEX('Онцгой татвар'!$C$6:$F$10,MATCH(I9,'Онцгой татвар'!$B$6:$B$10,1),MATCH(Q9,'Онцгой татвар'!$C$5:$F$5,1)),INDEX('Онцгой татвар'!$C$15:$F$19,MATCH(I9,'Онцгой татвар'!$B$15:$B$19,1),MATCH(Q9,'Онцгой татвар'!$C$14:$F$14,1))) -> 2500000 | S9: =IF(N9="","",((N9+IF(P9="",$D$3,P9))*$A$3+$F$3+R9)*(1+$H$3)) -> 33892898 | T9: =IF(O9="","",((O9+IF(P9="",$D$3,P9))*$A$3+$F$3+R9)*(1+$H$3)) | U9: 45613000 | V9: 43737000 | W9: 47427000 | X9: =IF(OR(U9="",S9=""),"",U9-S9) -> 11720102 | Y9: =IF(X9="","",X9/S9) -> 0.34579819 | Z9: =IF(OR(U9="",T9=""),"",U9-T9) | AA9: Өгөгдөл цөөн (8 зар) | AB9: гүйлт 114k +1.0%, өнгө -1.1% | AC9: 2026-10-06 | AE9: CAA Chubu|30344|2026/10/07
A10: 2026/10/07 11:10 | B10: CAA Chubu | C10: 90315 | D10: Prius Alpha | E10: ZVW41W | F10: S TOURING SELECTION | G10: 2011 | H10: 180000 | I10: 1800 | J10: Хайбрид | K10: RA | L10: мөнгөлөг | M10: Хүлээгдэж буй - хоцорсон | N10: 280000 | Q10: =$L$3-G10 -> 15 | R10: =IF(J10="Хайбрид",INDEX('Онцгой татвар'!$C$6:$F$10,MATCH(I10,'Онцгой татвар'!$B$6:$B$10,1),MATCH(Q10,'Онцгой татвар'!$C$5:$F$5,1)),INDEX('Онцгой татвар'!$C$15:$F$19,MATCH(I10,'Онцгой татвар'!$B$15:$B$19,1),MATCH(Q10,'Онцгой татвар'!$C$14:$F$14,1))) -> 5850000 | S10: =IF(N10="","",((N10+IF(P10="",$D$3,P10))*$A$3+$F$3+R10)*(1+$H$3)) -> 20017767 | T10: =IF(O10="","",((O10+IF(P10="",$D$3,P10))*$A$3+$F$3+R10)*(1+$H$3)) | U10: 27171000 | V10: 26053000 | W10: 28251000 | X10: =IF(OR(U10="",S10=""),"",U10-S10) -> 7153233 | Y10: =IF(X10="","",X10/S10) -> 0.3573442 | Z10: =IF(OR(U10="",T10=""),"",U10-T10) | AA10: Дунд (18 зар) | AB10: гүйлт 180k -0.7%, S Touring +4.0%, өнгө +7.1% | AC10: 2026-10-06 | AE10: CAA Chubu|90315|2026/10/07
A11: 2026/10/07 10:19 | B11: CAA Chubu | C11: 90061 | D11: Prius Alpha | E11: ZVW41W | F11: S TOURING SELECTION | G11: 2012 | H11: 134000 | I11: 1800 | J11: Хайбрид | K11: R | L11: сувдан цагаан | M11: Хүлээгдэж буй - тэргүүлж байна | N11: 300000 | Q11: =$L$3-G11 -> 14 | R11: =IF(J11="Хайбрид",INDEX('Онцгой татвар'!$C$6:$F$10,MATCH(I11,'Онцгой татвар'!$B$6:$B$10,1),MATCH(Q11,'Онцгой татвар'!$C$5:$F$5,1)),INDEX('Онцгой татвар'!$C$15:$F$19,MATCH(I11,'Онцгой татвар'!$B$15:$B$19,1),MATCH(Q11,'Онцгой татвар'!$C$14:$F$14,1))) -> 5850000 | S11: =IF(N11="","",((N11+IF(P11="",$D$3,P11))*$A$3+$F$3+R11)*(1+$H$3)) -> 20547450 | T11: =IF(O11="","",((O11+IF(P11="",$D$3,P11))*$A$3+$F$3+R11)*(1+$H$3)) | U11: 27151000 | V11: 26034000 | W11: 28231000 | X11: =IF(OR(U11="",S11=""),"",U11-S11) -> 6603550 | Y11: =IF(X11="","",X11/S11) -> 0.32138051 | Z11: =IF(OR(U11="",T11=""),"",U11-T11) | AA11: Найдвартай (47 зар) | AB11: гүйлт 134k +0.4%, S Touring +4.0%, өнгө +6.1% | AC11: 2026-10-06 | AE11: CAA Chubu|90061|2026/10/07
A12: 2026/10/07 10:01 | B12: MIRIVE Saitama | C12: 15144 | D12: Camry | E12: AXVH70 | F12: WS | G12: 2020 | H12: 118000 | I12: 2500 | J12: Хайбрид | K12: R | L12: хар | M12: Хүлээгдэж буй - тэргүүлж байна | N12: 1000000 | Q12: =$L$3-G12 -> 6 | R12: =IF(J12="Хайбрид",INDEX('Онцгой татвар'!$C$6:$F$10,MATCH(I12,'Онцгой татвар'!$B$6:$B$10,1),MATCH(Q12,'Онцгой татвар'!$C$5:$F$5,1)),INDEX('Онцгой татвар'!$C$15:$F$19,MATCH(I12,'Онцгой татвар'!$B$15:$B$19,1),MATCH(Q12,'Онцгой татвар'!$C$14:$F$14,1))) -> 1600000 | S12: =IF(N12="","",((N12+IF(P12="",$D$3,P12))*$A$3+$F$3+R12)*(1+$H$3)) -> 34177605 | T12: =IF(O12="","",((O12+IF(P12="",$D$3,P12))*$A$3+$F$3+R12)*(1+$H$3)) | U12: 54143000 | V12: 51916000 | W12: 56296000 | X12: =IF(OR(U12="",S12=""),"",U12-S12) -> 19965395 | Y12: =IF(X12="","",X12/S12) -> 0.58416601 | Z12: =IF(OR(U12="",T12=""),"",U12-T12) | AA12: Өгөгдөл цөөн (5 зар) | AB12: гүйлт 118k +1.7%, WS +10.9% | AC12: 2026-10-06 | AE12: MIRIVE Saitama|15144|2026/10/07
A13: 2026/10/07 09:18 | B13: CAA Chubu | C13: 10065 | D13: Prius Alpha | E13: ZVW41W | F13: G | G13: 2012 | H13: 159000 | I13: 1800 | J13: Хайбрид | K13: 3.5 | L13: сувдан цагаан | M13: Хүлээгдэж буй - хоцорсон | N13: 300000 | Q13: =$L$3-G13 -> 14 | R13: =IF(J13="Хайбрид",INDEX('Онцгой татвар'!$C$6:$F$10,MATCH(I13,'Онцгой татвар'!$B$6:$B$10,1),MATCH(Q13,'Онцгой татвар'!$C$5:$F$5,1)),INDEX('Онцгой татвар'!$C$15:$F$19,MATCH(I13,'Онцгой татвар'!$B$15:$B$19,1),MATCH(Q13,'Онцгой татвар'!$C$14:$F$14,1))) -> 5850000 | S13: =IF(N13="","",((N13+IF(P13="",$D$3,P13))*$A$3+$F$3+R13)*(1+$H$3)) -> 20547450 | T13: =IF(O13="","",((O13+IF(P13="",$D$3,P13))*$A$3+$F$3+R13)*(1+$H$3)) | U13: 25918000 | V13: 24852000 | W13: 26949000 | X13: =IF(OR(U13="",S13=""),"",U13-S13) -> 5370550 | Y13: =IF(X13="","",X13/S13) -> 0.26137307 | Z13: =IF(OR(U13="",T13=""),"",U13-T13) | AA13: Найдвартай (47 зар) | AB13: гүйлт 159k -0.2%, G +1.1%, өнгө +6.1%, оноо 3.5 -1.2% | AC13: 2026-10-06 | AE13: CAA Chubu|10065|2026/10/07
A14: 2026/10/07 09:11 | B14: MIRIVE Saitama | C14: 15027 | D14: Camry | E14: AXVH70 | F14: X | G14: 2017 | H14: 116000 | I14: 2500 | J14: Хайбрид | K14: 4 | L14: улаан | M14: Хүлээгдэж буй - тэргүүлж байна | N14: 900000 | Q14: =$L$3-G14 -> 9 | R14: =IF(J14="Хайбрид",INDEX('Онцгой татвар'!$C$6:$F$10,MATCH(I14,'Онцгой татвар'!$B$6:$B$10,1),MATCH(Q14,'Онцгой татвар'!$C$5:$F$5,1)),INDEX('Онцгой татвар'!$C$15:$F$19,MATCH(I14,'Онцгой татвар'!$B$15:$B$19,1),MATCH(Q14,'Онцгой татвар'!$C$14:$F$14,1))) -> 2500000 | S14: =IF(N14="","",((N14+IF(P14="",$D$3,P14))*$A$3+$F$3+R14)*(1+$H$3)) -> 32568690 | T14: =IF(O14="","",((O14+IF(P14="",$D$3,P14))*$A$3+$F$3+R14)*(1+$H$3)) | U14: 36718000 | V14: 35208000 | W14: 38179000 | X14: =IF(OR(U14="",S14=""),"",U14-S14) -> 4149310 | Y14: =IF(X14="","",X14/S14) -> 0.12740181 | Z14: =IF(OR(U14="",T14=""),"",U14-T14) | AA14: Дунд (15 зар) | AB14: гүйлт 116k +0.7%, X -16.6%, өнгө -1.1%, оноо 4 +0.8% | AC14: 2026-10-06 | AE14: MIRIVE Saitama|15027|2026/10/07
A15: 2026/10/07 09:01 | B15: CAA Chubu | C15: 10005 | D15: Prius Alpha | E15: ZVW41W | F15: S TOURING SELECTION | G15: 2011 | H15: 132000 | I15: 1800 | J15: Хайбрид | K15: 3.5 | L15: хар | M15: Хүлээгдэж буй - тэргүүлж байна | N15: 275000 | Q15: =$L$3-G15 -> 15 | R15: =IF(J15="Хайбрид",INDEX('Онцгой татвар'!$C$6:$F$10,MATCH(I15,'Онцгой татвар'!$B$6:$B$10,1),MATCH(Q15,'Онцгой татвар'!$C$5:$F$5,1)),INDEX('Онцгой татвар'!$C$15:$F$19,MATCH(I15,'Онцгой татвар'!$B$15:$B$19,1),MATCH(Q15,'Онцгой татвар'!$C$14:$F$14,1))) -> 5850000 | S15: =IF(N15="","",((N15+IF(P15="",$D$3,P15))*$A$3+$F$3+R15)*(1+$H$3)) -> 19885346 | T15: =IF(O15="","",((O15+IF(P15="",$D$3,P15))*$A$3+$F$3+R15)*(1+$H$3)) | U15: 25321000 | V15: 24279000 | W15: 26328000 | X15: =IF(OR(U15="",S15=""),"",U15-S15) -> 5435653.8 | Y15: =IF(X15="","",X15/S15) -> 0.27334972 | Z15: =IF(OR(U15="",T15=""),"",U15-T15) | AA15: Дунд (18 зар) | AB15: гүйлт 132k +0.4%, S Touring +4.0%, оноо 3.5 -1.2% | AC15: 2026-10-06 | AE15: CAA Chubu|10005|2026/10/07
A16: 2026/10/06 12:38 | B16: TAA Kinki | C16: 70060 | D16: Camry | E16: AXVH70 | F16: G | G16: 2017 | H16: 111000 | I16: 2500 | J16: Хайбрид | K16: 3.5 | L16: сувдан цагаан | M16: Аваагүй (өөр хүнд) | N16: 980000 | O16: 1294000 | Q16: =$L$3-G16 -> 9 | R16: =IF(J16="Хайбрид",INDEX('Онцгой татвар'!$C$6:$F$10,MATCH(I16,'Онцгой татвар'!$B$6:$B$10,1),MATCH(Q16,'Онцгой татвар'!$C$5:$F$5,1)),INDEX('Онцгой татвар'!$C$15:$F$19,MATCH(I16,'Онцгой татвар'!$B$15:$B$19,1),MATCH(Q16,'Онцгой татвар'!$C$14:$F$14,1))) -> 2500000 | S16: =IF(N16="","",((N16+IF(P16="",$D$3,P16))*$A$3+$F$3+R16)*(1+$H$3)) -> 34687422 | T16: =IF(O16="","",((O16+IF(P16="",$D$3,P16))*$A$3+$F$3+R16)*(1+$H$3)) -> 43003445 | U16: 46298000 | V16: 44394000 | W16: 48139000 | X16: =IF(OR(U16="",S16=""),"",U16-S16) -> 11610578 | Y16: =IF(X16="","",X16/S16) -> 0.33472012 | Z16: =IF(OR(U16="",T16=""),"",U16-T16) -> 3294554.9 | AA16: Дунд (15 зар) | AB16: гүйлт 111k +0.7%, өнгө +6.1%, оноо 3.5 -1.2% | AC16: 2026-10-05 | AE16: TAA Kinki|70060|2026/10/06
A17: 2026/10/06 12:21 | B17: TAA Kinki | C17: 665 | D17: Prius Alpha | E17: ZVW41W | F17: S TOURING SELECTION | G17: 2014 | H17: 165000 | I17: 1800 | J17: Хайбрид | K17: 3.5 | L17: саарал | M17: Аваагүй (өөр хүнд) | N17: 275000 | O17: 473000 | Q17: =$L$3-G17 -> 12 | R17: =IF(J17="Хайбрид",INDEX('Онцгой татвар'!$C$6:$F$10,MATCH(I17,'Онцгой татвар'!$B$6:$B$10,1),MATCH(Q17,'Онцгой татвар'!$C$5:$F$5,1)),INDEX('Онцгой татвар'!$C$15:$F$19,MATCH(I17,'Онцгой татвар'!$B$15:$B$19,1),MATCH(Q17,'Онцгой татвар'!$C$14:$F$14,1))) -> 5850000 | S17: =IF(N17="","",((N17+IF(P17="",$D$3,P17))*$A$3+$F$3+R17)*(1+$H$3)) -> 19885346 | T17: =IF(O17="","",((O17+IF(P17="",$D$3,P17))*$A$3+$F$3+R17)*(1+$H$3)) -> 25129208 | U17: 28624000 | V17: 27446000 | W17: 29762000 | X17: =IF(OR(U17="",S17=""),"",U17-S17) -> 8738653.8 | Y17: =IF(X17="","",X17/S17) -> 0.43945193 | Z17: =IF(OR(U17="",T17=""),"",U17-T17) -> 3494792 | AA17: Дунд (17 зар) | AB17: гүйлт 165k -0.5%, S Touring +4.0%, өнгө +1.8%, оноо 3.5 -1.2% | AC17: 2026-10-05 | AE17: TAA Kinki|665|2026/10/06
A18: 2026/10/06 12:07 | B18: TAA Kinki | C18: 620 | D18: Prius Alpha | E18: ZVW40W | F18: S TUNE BLACK | G18: 2014 | H18: 156000 | I18: 1800 | J18: Хайбрид | K18: RA | L18: хар | M18: Аваагүй (өөр хүнд) | N18: 280000 | O18: 409000 | Q18: =$L$3-G18 -> 12 | R18: =IF(J18="Хайбрид",INDEX('Онцгой татвар'!$C$6:$F$10,MATCH(I18,'Онцгой татвар'!$B$6:$B$10,1),MATCH(Q18,'Онцгой татвар'!$C$5:$F$5,1)),INDEX('Онцгой татвар'!$C$15:$F$19,MATCH(I18,'Онцгой татвар'!$B$15:$B$19,1),MATCH(Q18,'Онцгой татвар'!$C$14:$F$14,1))) -> 5850000 | S18: =IF(N18="","",((N18+IF(P18="",$D$3,P18))*$A$3+$F$3+R18)*(1+$H$3)) -> 20017767 | T18: =IF(O18="","",((O18+IF(P18="",$D$3,P18))*$A$3+$F$3+R18)*(1+$H$3)) -> 23434222 | U18: 28687000 | V18: 27507000 | W18: 29828000 | X18: =IF(OR(U18="",S18=""),"",U18-S18) -> 8669233 | Y18: =IF(X18="","",X18/S18) -> 0.43307693 | Z18: =IF(OR(U18="",T18=""),"",U18-T18) -> 5252777.7 | AA18: Дунд (17 зар) | AB18: 7 суудал +3.6%, гүйлт 156k -0.2%, S Tune Black +0.8% | AC18: 2026-10-05 | AE18: TAA Kinki|620|2026/10/06
A19: 2026/10/06 11:44 | B19: TAA Kyushu | C19: 9048 | D19: Prius Alpha | E19: ZVW40W | F19: G | G19: 2011 | H19: 185000 | I19: 1800 | J19: Хайбрид | K19: RA | L19: сувдан цагаан | M19: Аваагүй (өөр хүнд) | N19: 275000 | O19: 340000 | Q19: =$L$3-G19 -> 15 | R19: =IF(J19="Хайбрид",INDEX('Онцгой татвар'!$C$6:$F$10,MATCH(I19,'Онцгой татвар'!$B$6:$B$10,1),MATCH(Q19,'Онцгой татвар'!$C$5:$F$5,1)),INDEX('Онцгой татвар'!$C$15:$F$19,MATCH(I19,'Онцгой татвар'!$B$15:$B$19,1),MATCH(Q19,'Онцгой татвар'!$C$14:$F$14,1))) -> 5850000 | S19: =IF(N19="","",((N19+IF(P19="",$D$3,P19))*$A$3+$F$3+R19)*(1+$H$3)) -> 19885346 | T19: =IF(O19="","",((O19+IF(P19="",$D$3,P19))*$A$3+$F$3+R19)*(1+$H$3)) -> 21606816 | U19: 27087000 | V19: 25973000 | W19: 28165000 | X19: =IF(OR(U19="",S19=""),"",U19-S19) -> 7201653.8 | Y19: =IF(X19="","",X19/S19) -> 0.36215883 | Z19: =IF(OR(U19="",T19=""),"",U19-T19) -> 5480184 | AA19: Дунд (18 зар) | AB19: 7 суудал +3.6%, гүйлт 185k -0.8%, G +1.1%, өнгө +6.1% | AC19: 2026-10-05 | AE19: TAA Kyushu|9048|2026/10/06
A20: 2026/10/06 11:00 | B20: TAA Kyushu | C20: 6130 | D20: Camry | E20: AXVH70 | F20: WS | G20: 2018 | H20: 145000 | I20: 2500 | J20: Хайбрид | K20: 4 | L20: сувдан цагаан | M20: Аваагүй (өөр хүнд) | N20: 1000000 | O20: 1462000 | Q20: =$L$3-G20 -> 8 | R20: =IF(J20="Хайбрид",INDEX('Онцгой татвар'!$C$6:$F$10,MATCH(I20,'Онцгой татвар'!$B$6:$B$10,1),MATCH(Q20,'Онцгой татвар'!$C$5:$F$5,1)),INDEX('Онцгой татвар'!$C$15:$F$19,MATCH(I20,'Онцгой татвар'!$B$15:$B$19,1),MATCH(Q20,'Онцгой татвар'!$C$14:$F$14,1))) -> 2500000 | S20: =IF(N20="","",((N20+IF(P20="",$D$3,P20))*$A$3+$F$3+R20)*(1+$H$3)) -> 35217105 | T20: =IF(O20="","",((O20+IF(P20="",$D$3,P20))*$A$3+$F$3+R20)*(1+$H$3)) -> 47452782 | U20: 54293000 | V20: 52060000 | W20: 56453000 | X20: =IF(OR(U20="",S20=""),"",U20-S20) -> 19075895 | Y20: =IF(X20="","",X20/S20) -> 0.54166562 | Z20: =IF(OR(U20="",T20=""),"",U20-T20) -> 6840217.7 | AA20: Өгөгдөл цөөн (8 зар) | AB20: гүйлт 145k +0.2%, WS +10.9%, өнгө +6.1%, оноо 4 +0.8% | AC20: 2026-10-05 | AE20: TAA Kyushu|6130|2026/10/06
A21: 2026/10/06 10:57 | B21: TAA Kinki | C21: 387 | D21: Prius | E21: ZVW51 | F21: A | G21: 2017 | H21: 136000 | I21: 1800 | J21: Хайбрид | K21: RA | L21: мөнгөлөг | M21: Аваагүй (өөр хүнд) | N21: 660000 | O21: 667000 | Q21: =$L$3-G21 -> 9 | R21: =IF(J21="Хайбрид",INDEX('Онцгой татвар'!$C$6:$F$10,MATCH(I21,'Онцгой татвар'!$B$6:$B$10,1),MATCH(Q21,'Онцгой татвар'!$C$5:$F$5,1)),INDEX('Онцгой татвар'!$C$15:$F$19,MATCH(I21,'Онцгой татвар'!$B$15:$B$19,1),MATCH(Q21,'Онцгой татвар'!$C$14:$F$14,1))) -> 2500000 | S21: =IF(N21="","",((N21+IF(P21="",$D$3,P21))*$A$3+$F$3+R21)*(1+$H$3)) -> 26212494 | T21: =IF(O21="","",((O21+IF(P21="",$D$3,P21))*$A$3+$F$3+R21)*(1+$H$3)) -> 26397883 | U21: 34277000 | V21: 32867000 | W21: 35640000 | X21: =IF(OR(U21="",S21=""),"",U21-S21) -> 8064506 | Y21: =IF(X21="","",X21/S21) -> 0.30765886 | Z21: =IF(OR(U21="",T21=""),"",U21-T21) -> 7879117 | AA21: Найдвартай (32 зар) | AB21: ZVW51 +7.1%, гүйлт 136k +0.2%, A +4.0%, өнгө +7.1% | AC21: 2026-10-05 | AE21: TAA Kinki|387|2026/10/06
A22: 2026/10/06 10:40 | B22: CAA Gifu | C22: 30167 | D22: Prius Alpha | E22: ZVW40W | F22: G | G22: 2011 | H22: 149000 | I22: 1800 | J22: Хайбрид | K22: 3.5 | L22: сувдан цагаан | M22: Аваагүй (өөр хүнд) | N22: 305000 | O22: 423000 | Q22: =$L$3-G22 -> 15 | R22: =IF(J22="Хайбрид",INDEX('Онцгой татвар'!$C$6:$F$10,MATCH(I22,'Онцгой татвар'!$B$6:$B$10,1),MATCH(Q22,'Онцгой татвар'!$C$5:$F$5,1)),INDEX('Онцгой татвар'!$C$15:$F$19,MATCH(I22,'Онцгой татвар'!$B$15:$B$19,1),MATCH(Q22,'Онцгой татвар'!$C$14:$F$14,1))) -> 5850000 | S22: =IF(N22="","",((N22+IF(P22="",$D$3,P22))*$A$3+$F$3+R22)*(1+$H$3)) -> 20679871 | T22: =IF(O22="","",((O22+IF(P22="",$D$3,P22))*$A$3+$F$3+R22)*(1+$H$3)) -> 23805000 | U22: 26983000 | V22: 25874000 | W22: 28057000 | X22: =IF(OR(U22="",S22=""),"",U22-S22) -> 6303129.2 | Y22: =IF(X22="","",X22/S22) -> 0.30479539 | Z22: =IF(OR(U22="",T22=""),"",U22-T22) -> 3177999.5 | AA22: Дунд (18 зар) | AB22: 7 суудал +3.6%, G +1.1%, өнгө +6.1%, оноо 3.5 -1.2% | AC22: 2026-10-05 | AE22: CAA Gifu|30167|2026/10/06
A23: 2026/10/06 10:19 | B23: CAA Tokyo | C23: 30044 | D23: Prius | E23: ZVW50 | F23: S TOURING SELECTION | G23: 2018 | H23: 205000 | I23: 1800 | J23: Хайбрид | K23: 3.5 | L23: сувдан цагаан | M23: Аваагүй (өөр хүнд) | N23: 500000 | O23: 685000 | Q23: =$L$3-G23 -> 8 | R23: =IF(J23="Хайбрид",INDEX('Онцгой татвар'!$C$6:$F$10,MATCH(I23,'Онцгой татвар'!$B$6:$B$10,1),MATCH(Q23,'Онцгой татвар'!$C$5:$F$5,1)),INDEX('Онцгой татвар'!$C$15:$F$19,MATCH(I23,'Онцгой татвар'!$B$15:$B$19,1),MATCH(Q23,'Онцгой татвар'!$C$14:$F$14,1))) -> 2500000 | S23: =IF(N23="","",((N23+IF(P23="",$D$3,P23))*$A$3+$F$3+R23)*(1+$H$3)) -> 21975030 | T23: =IF(O23="","",((O23+IF(P23="",$D$3,P23))*$A$3+$F$3+R23)*(1+$H$3)) -> 26874598 | U23: 32969000 | V23: 31613000 | W23: 34280000 | X23: =IF(OR(U23="",S23=""),"",U23-S23) -> 10993970 | Y23: =IF(X23="","",X23/S23) -> 0.50029374 | Z23: =IF(OR(U23="",T23=""),"",U23-T23) -> 6094402.2 | AA23: Өгөгдөл цөөн (7 зар) | AB23: гүйлт 205k -1.9%, S Touring +5.8%, өнгө +6.1%, оноо 3.5 -1.2% | AC23: 2026-10-05 | AE23: CAA Tokyo|30044|2026/10/06
A24: 2026/10/06 10:11 | B24: CAA Tokyo | C24: 10318 | D24: Prius Alpha | E24: ZVW41W | F24: S TOURING SELECTION | G24: 2012 | H24: 161000 | I24: 1800 | J24: Хайбрид | K24: 3.5 | L24: сувдан цагаан | M24: Аваагүй (өөр хүнд) | N24: 295000 | O24: 426000 | Q24: =$L$3-G24 -> 14 | R24: =IF(J24="Хайбрид",INDEX('Онцгой татвар'!$C$6:$F$10,MATCH(I24,'Онцгой татвар'!$B$6:$B$10,1),MATCH(Q24,'Онцгой татвар'!$C$5:$F$5,1)),INDEX('Онцгой татвар'!$C$15:$F$19,MATCH(I24,'Онцгой татвар'!$B$15:$B$19,1),MATCH(Q24,'Онцгой татвар'!$C$14:$F$14,1))) -> 5850000 | S24: =IF(N24="","",((N24+IF(P24="",$D$3,P24))*$A$3+$F$3+R24)*(1+$H$3)) -> 20415029 | T24: =IF(O24="","",((O24+IF(P24="",$D$3,P24))*$A$3+$F$3+R24)*(1+$H$3)) -> 23884453 | U24: 26634000 | V24: 25539000 | W24: 27694000 | X24: =IF(OR(U24="",S24=""),"",U24-S24) -> 6218970.8 | Y24: =IF(X24="","",X24/S24) -> 0.30462708 | Z24: =IF(OR(U24="",T24=""),"",U24-T24) -> 2749547.1 | AA24: Найдвартай (47 зар) | AB24: гүйлт 161k -0.3%, S Touring +4.0%, өнгө +6.1%, оноо 3.5 -1.2% | AC24: 2026-10-05 | AE24: CAA Tokyo|10318|2026/10/06
A25: 2026/10/06 09:54 | B25: TAA Kinki | C25: 180 | D25: Prius Alpha | E25: ZVW41W | F25: G | G25: 2012 | H25: 160000 | I25: 1800 | J25: Хайбрид | K25: 3.5 | L25: мөнгөлөг | M25: Аваагүй (өөр хүнд) | N25: 270000 | O25: 334000 | Q25: =$L$3-G25 -> 14 | R25: =IF(J25="Хайбрид",INDEX('Онцгой татвар'!$C$6:$F$10,MATCH(I25,'Онцгой татвар'!$B$6:$B$10,1),MATCH(Q25,'Онцгой татвар'!$C$5:$F$5,1)),INDEX('Онцгой татвар'!$C$15:$F$19,MATCH(I25,'Онцгой татвар'!$B$15:$B$19,1),MATCH(Q25,'Онцгой татвар'!$C$14:$F$14,1))) -> 5850000 | S25: =IF(N25="","",((N25+IF(P25="",$D$3,P25))*$A$3+$F$3+R25)*(1+$H$3)) -> 19752926 | T25: =IF(O25="","",((O25+IF(P25="",$D$3,P25))*$A$3+$F$3+R25)*(1+$H$3)) -> 21447911 | U25: 26164000 | V25: 25088000 | W25: 27204000 | X25: =IF(OR(U25="",S25=""),"",U25-S25) -> 6411074.5 | Y25: =IF(X25="","",X25/S25) -> 0.32456329 | Z25: =IF(OR(U25="",T25=""),"",U25-T25) -> 4716088.9 | AA25: Найдвартай (47 зар) | AB25: гүйлт 160k -0.3%, G +1.1%, өнгө +7.1%, оноо 3.5 -1.2% | AC25: 2026-10-05 | AE25: TAA Kinki|180|2026/10/06
A26: 2026/10/06 09:50 | B26: TAA Hiroshima | C26: 174 | D26: Prius | E26: ZVW51 | F26: A PREMIUM | G26: 2017 | H26: 189000 | I26: 1800 | J26: Хайбрид | K26: 3.5 | L26: цагаан | M26: Аваагүй (өөр хүнд) | N26: 530000 | O26: 687000 | Q26: =$L$3-G26 -> 9 | R26: =IF(J26="Хайбрид",INDEX('Онцгой татвар'!$C$6:$F$10,MATCH(I26,'Онцгой татвар'!$B$6:$B$10,1),MATCH(Q26,'Онцгой татвар'!$C$5:$F$5,1)),INDEX('Онцгой татвар'!$C$15:$F$19,MATCH(I26,'Онцгой татвар'!$B$15:$B$19,1),MATCH(Q26,'Онцгой татвар'!$C$14:$F$14,1))) -> 2500000 | S26: =IF(N26="","",((N26+IF(P26="",$D$3,P26))*$A$3+$F$3+R26)*(1+$H$3)) -> 22769554 | T26: =IF(O26="","",((O26+IF(P26="",$D$3,P26))*$A$3+$F$3+R26)*(1+$H$3)) -> 26927566 | U26: 34406000 | V26: 32991000 | W26: 35775000 | X26: =IF(OR(U26="",S26=""),"",U26-S26) -> 11636446 | Y26: =IF(X26="","",X26/S26) -> 0.51105284 | Z26: =IF(OR(U26="",T26=""),"",U26-T26) -> 7478434 | AA26: Найдвартай (32 зар) | AB26: ZVW51 +7.1%, гүйлт 189k -1.0%, A Premium +10.5%, өнгө +3.8%, оноо 3.5 -1.2% | AC26: 2026-10-05 | AE26: TAA Hiroshima|174|2026/10/06
A27: 2026/10/06 09:37 | B27: CAA Tokyo | C27: 10170 | D27: Prius Alpha | E27: ZVW41W | F27: G TOURING SELECTION | G27: 2012 | H27: 169000 | I27: 1800 | J27: Хайбрид | K27: 3.5 | L27: сувдан цагаан | M27: Аваагүй (өөр хүнд) | N27: 295000 | O27: 429000 | Q27: =$L$3-G27 -> 14 | R27: =IF(J27="Хайбрид",INDEX('Онцгой татвар'!$C$6:$F$10,MATCH(I27,'Онцгой татвар'!$B$6:$B$10,1),MATCH(Q27,'Онцгой татвар'!$C$5:$F$5,1)),INDEX('Онцгой татвар'!$C$15:$F$19,MATCH(I27,'Онцгой татвар'!$B$15:$B$19,1),MATCH(Q27,'Онцгой татвар'!$C$14:$F$14,1))) -> 5850000 | S27: =IF(N27="","",((N27+IF(P27="",$D$3,P27))*$A$3+$F$3+R27)*(1+$H$3)) -> 20415029 | T27: =IF(O27="","",((O27+IF(P27="",$D$3,P27))*$A$3+$F$3+R27)*(1+$H$3)) -> 23963905 | U27: 26387000 | V27: 25302000 | W27: 27436000 | X27: =IF(OR(U27="",S27=""),"",U27-S27) -> 5971970.8 | Y27: =IF(X27="","",X27/S27) -> 0.29252815 | Z27: =IF(OR(U27="",T27=""),"",U27-T27) -> 2423094.6 | AA27: Найдвартай (47 зар) | AB27: гүйлт 169k -0.5%, G Touring +3.2%, өнгө +6.1%, оноо 3.5 -1.2% | AC27: 2026-10-05 | AE27: CAA Tokyo|10170|2026/10/06
... A29: 2026/10/05 14:40 | B29: Honda Nagoya | C29: 55383 | D29: Prius Alpha | E29: ZVW41W | F29: G | G29: 2014 | H29: 98000 | I29: 1800 | J29: Хайбрид | K29: R | L29: мөнгөлөг | M29: Аваагүй (өөр хүнд) | N29: 300000 | O29: 423000 | Q29: =$L$3-G29 -> 12 | R29: =IF(J29="Хайбрид",INDEX('Онцгой татвар'!$C$6:$F$10,MATCH(I29,'Онцгой татвар'!$B$6:$B$10,1),MATCH(Q29,'Онцгой татвар'!$C$5:$F$5,1)),INDEX('Онцгой татвар'!$C$15:$F$19,MATCH(I29,'Онцгой татвар'!$B$15:$B$19,1),MATCH(Q29,'Онцгой татвар'!$C$14:$F$14,1))) -> 5850000 | S29: =IF(N29="","",((N29+IF(P29="",$D$3,P29))*$A$3+$F$3+R29)*(1+$H$3)) -> 20547450 | T29: =IF(O29="","",((O29+IF(P29="",$D$3,P29))*$A$3+$F$3+R29)*(1+$H$3)) -> 23805000 | U29: 30251000 | V29: 29006000 | W29: 31454000 | X29: =IF(OR(U29="",S29=""),"",U29-S29) -> 9703550 | Y29: =IF(X29="","",X29/S29) -> 0.47225081 | Z29: =IF(OR(U29="",T29=""),"",U29-T29) -> 6445999.5 | AA29: Дунд (17 зар) | AB29: гүйлт 98k +1.5%, G +1.1%, өнгө +7.1% | AC29: 2026-10-05 | AE29: Honda Nagoya|55383|2026/10/05
A30: 2026/10/05 14:01 | B30: JU Tokyo | C30: 8437 | D30: Prius Alpha | E30: ZVW41W | F30: G | G30: 2012 | H30: 209000 | I30: 1800 | J30: Хайбрид | K30: 3.5 | L30: саарал | M30: Car Problem | N30: 220000 | Q30: =$L$3-G30 -> 14 | R30: =IF(J30="Хайбрид",INDEX('Онцгой татвар'!$C$6:$F$10,MATCH(I30,'Онцгой татвар'!$B$6:$B$10,1),MATCH(Q30,'Онцгой татвар'!$C$5:$F$5,1)),INDEX('Онцгой татвар'!$C$15:$F$19,MATCH(I30,'Онцгой татвар'!$B$15:$B$19,1),MATCH(Q30,'Онцгой татвар'!$C$14:$F$14,1))) -> 5850000 | S30: =IF(N30="","",((N30+IF(P30="",$D$3,P30))*$A$3+$F$3+R30)*(1+$H$3)) -> 18428718 | T30: =IF(O30="","",((O30+IF(P30="",$D$3,P30))*$A$3+$F$3+R30)*(1+$H$3)) | U30: 24522000 | V30: 23514000 | W30: 25498000 | X30: =IF(OR(U30="",S30=""),"",U30-S30) -> 6093282 | Y30: =IF(X30="","",X30/S30) -> 0.33064058 | Z30: =IF(OR(U30="",T30=""),"",U30-T30) | AA30: Найдвартай (47 зар) | AB30: гүйлт 209k -1.6%, G +1.1%, өнгө +1.8%, оноо 3.5 -1.2% | AC30: 2026-10-05 | AE30: JU Tokyo|8437|2026/10/05
A31: 2026/10/05 13:47 | B31: Honda Tokyo | C31: 20287 | D31: Prius Alpha | E31: ZVW41W | F31: S TUNE BLACK | G31: 2014 | H31: 140000 | I31: 1800 | J31: Хайбрид | K31: R | L31: хар | M31: Аваагүй (өөр хүнд) | N31: 220000 | O31: 311000 | Q31: =$L$3-G31 -> 12 | R31: =IF(J31="Хайбрид",INDEX('Онцгой татвар'!$C$6:$F$10,MATCH(I31,'Онцгой татвар'!$B$6:$B$10,1),MATCH(Q31,'Онцгой татвар'!$C$5:$F$5,1)),INDEX('Онцгой татвар'!$C$15:$F$19,MATCH(I31,'Онцгой татвар'!$B$15:$B$19,1),MATCH(Q31,'Онцгой татвар'!$C$14:$F$14,1))) -> 5850000 | S31: =IF(N31="","",((N31+IF(P31="",$D$3,P31))*$A$3+$F$3+R31)*(1+$H$3)) -> 18428718 | T31: =IF(O31="","",((O31+IF(P31="",$D$3,P31))*$A$3+$F$3+R31)*(1+$H$3)) -> 20838776 | U31: 27823000 | V31: 26679000 | W31: 28930000 | X31: =IF(OR(U31="",S31=""),"",U31-S31) -> 9394282 | Y31: =IF(X31="","",X31/S31) -> 0.50976319 | Z31: =IF(OR(U31="",T31=""),"",U31-T31) -> 6984224.3 | AA31: Дунд (17 зар) | AB31: гүйлт 140k +0.3%, S Tune Black +0.8% | AC31: 2026-10-05 | AE31: Honda Tokyo|20287|2026/10/05
A32: 2026/10/05 12:29 | B32: Honda Sendai | C32: 40063 | D32: Prius Alpha | E32: ZVW41W | F32: S TUNE BLACK | G32: 2013 | H32: 163000 | I32: 1800 | J32: Хайбрид | K32: 3.5 | L32: сувдан цагаан | M32: Аваагүй (өөр хүнд) | N32: 285000 | O32: 365000 | Q32: =$L$3-G32 -> 13 | R32: =IF(J32="Хайбрид",INDEX('Онцгой татвар'!$C$6:$F$10,MATCH(I32,'Онцгой татвар'!$B$6:$B$10,1),MATCH(Q32,'Онцгой татвар'!$C$5:$F$5,1)),INDEX('Онцгой татвар'!$C$15:$F$19,MATCH(I32,'Онцгой татвар'!$B$15:$B$19,1),MATCH(Q32,'Онцгой татвар'!$C$14:$F$14,1))) -> 5850000 | S32: =IF(N32="","",((N32+IF(P32="",$D$3,P32))*$A$3+$F$3+R32)*(1+$H$3)) -> 20150188 | T32: =IF(O32="","",((O32+IF(P32="",$D$3,P32))*$A$3+$F$3+R32)*(1+$H$3)) -> 22268920 | U32: 26726000 | V32: 25627000 | W32: 27789000 | X32: =IF(OR(U32="",S32=""),"",U32-S32) -> 6575812.2 | Y32: =IF(X32="","",X32/S32) -> 0.32634 | Z32: =IF(OR(U32="",T32=""),"",U32-T32) -> 4457080.2 | AA32: Найдвартай (40 зар) | AB32: гүйлт 163k -0.4%, S Tune Black +0.8%, өнгө +6.1%, оноо 3.5 -1.2% | AC32: 2026-10-05 | AE32: Honda Sendai|40063|2026/10/05
A33: 2026/10/05 11:47 | B33: JU Tokyo | C33: 7045 | D33: Prius Alpha | E33: ZVW41W | F33: G TOURING SELECTION | G33: 2014 | H33: 119000 | I33: 1800 | J33: Хайбрид | K33: 3.5 | L33: хар | M33: Аваагүй (өөр хүнд) | N33: 280000 | O33: 450000 | Q33: =$L$3-G33 -> 12 | R33: =IF(J33="Хайбрид",INDEX('Онцгой татвар'!$C$6:$F$10,MATCH(I33,'Онцгой татвар'!$B$6:$B$10,1),MATCH(Q33,'Онцгой татвар'!$C$5:$F$5,1)),INDEX('Онцгой татвар'!$C$15:$F$19,MATCH(I33,'Онцгой татвар'!$B$15:$B$19,1),MATCH(Q33,'Онцгой татвар'!$C$14:$F$14,1))) -> 5850000 | S33: =IF(N33="","",((N33+IF(P33="",$D$3,P33))*$A$3+$F$3+R33)*(1+$H$3)) -> 20017767 | T33: =IF(O33="","",((O33+IF(P33="",$D$3,P33))*$A$3+$F$3+R33)*(1+$H$3)) -> 24520072 | U33: 28311000 | V33: 27147000 | W33: 29437000 | X33: =IF(OR(U33="",S33=""),"",U33-S33) -> 8293233 | Y33: =IF(X33="","",X33/S33) -> 0.41429361 | Z33: =IF(OR(U33="",T33=""),"",U33-T33) -> 3790927.5 | AA33: Дунд (17 зар) | AB33: гүйлт 119k +0.9%, G Touring +3.2%, оноо 3.5 -1.2% | AC33: 2026-10-05 | AE33: JU Tokyo|7045|2026/10/05
A34: 2026/10/05 11:34 | B34: Honda Nagoya | C34: 55070 | D34: Prius Alpha | E34: ZVW41W | F34: S | G34: 2012 | H34: 100000 | I34: 1800 | J34: Хайбрид | K34: 4 | L34: сувдан цагаан | M34: Аваагүй (өөр хүнд) | N34: 301000 | O34: 443000 | Q34: =$L$3-G34 -> 14 | R34: =IF(J34="Хайбрид",INDEX('Онцгой татвар'!$C$6:$F$10,MATCH(I34,'Онцгой татвар'!$B$6:$B$10,1),MATCH(Q34,'Онцгой татвар'!$C$5:$F$5,1)),INDEX('Онцгой татвар'!$C$15:$F$19,MATCH(I34,'Онцгой татвар'!$B$15:$B$19,1),MATCH(Q34,'Онцгой татвар'!$C$14:$F$14,1))) -> 5850000 | S34: =IF(N34="","",((N34+IF(P34="",$D$3,P34))*$A$3+$F$3+R34)*(1+$H$3)) -> 20573934 | T34: =IF(O34="","",((O34+IF(P34="",$D$3,P34))*$A$3+$F$3+R34)*(1+$H$3)) -> 24334683 | U34: 26516000 | V34: 25425000 | W34: 27570000 | X34: =IF(OR(U34="",S34=""),"",U34-S34) -> 5942065.8 | Y34: =IF(X34="","",X34/S34) -> 0.28881525 | Z34: =IF(OR(U34="",T34=""),"",U34-T34) -> 2181316.5 | AA34: Найдвартай (47 зар) | AB34: гүйлт 100k +1.1%, өнгө +6.1%, оноо 4 +0.8% | AC34: 2026-10-05 | AE34: Honda Nagoya|55070|2026/10/05
A35: 2026/10/05 11:09 | B35: Honda Tokyo | C35: 20017 | D35: Prius Alpha | E35: ZVW41W | F35: S TOURING SELECTION | G35: 2012 | H35: 177000 | I35: 1800 | J35: Хайбрид | K35: 3.5 | L35: цагаан | M35: Аваагүй (өөр хүнд) | N35: 290000 | O35: 410000 | Q35: =$L$3-G35 -> 14 | R35: =IF(J35="Хайбрид",INDEX('Онцгой татвар'!$C$6:$F$10,MATCH(I35,'Онцгой татвар'!$B$6:$B$10,1),MATCH(Q35,'Онцгой татвар'!$C$5:$F$5,1)),INDEX('Онцгой татвар'!$C$15:$F$19,MATCH(I35,'Онцгой татвар'!$B$15:$B$19,1),MATCH(Q35,'Онцгой татвар'!$C$14:$F$14,1))) -> 5850000 | S35: =IF(N35="","",((N35+IF(P35="",$D$3,P35))*$A$3+$F$3+R35)*(1+$H$3)) -> 20282608 | T35: =IF(O35="","",((O35+IF(P35="",$D$3,P35))*$A$3+$F$3+R35)*(1+$H$3)) -> 23460706 | U35: 25937000 | V35: 24870000 | W35: 26968000 | X35: =IF(OR(U35="",S35=""),"",U35-S35) -> 5654391.5 | Y35: =IF(X35="","",X35/S35) -> 0.27878029 | Z35: =IF(OR(U35="",T35=""),"",U35-T35) -> 2476293.5 | AA35: Найдвартай (47 зар) | AB35: гүйлт 177k -0.7%, S Touring +4.0%, өнгө +3.8%, оноо 3.5 -1.2% | AC35: 2026-10-05 | AE35: Honda Tokyo|20017|2026/10/05
A36: 2026/10/05 10:46 | B36: Honda Kansai | C36: 70032 | D36: Prius Alpha | E36: ZVW41W | F36: G | G36: 2013 | H36: 107000 | I36: 1800 | J36: Хайбрид | K36: 3 | L36: мөнгөлөг | M36: Аваагүй (өөр хүнд) | N36: 280000 | O36: 331000 | Q36: =$L$3-G36 -> 13 | R36: =IF(J36="Хайбрид",INDEX('Онцгой татвар'!$C$6:$F$10,MATCH(I36,'Онцгой татвар'!$B$6:$B$10,1),MATCH(Q36,'Онцгой татвар'!$C$5:$F$5,1)),INDEX('Онцгой татвар'!$C$15:$F$19,MATCH(I36,'Онцгой татвар'!$B$15:$B$19,1),MATCH(Q36,'Онцгой татвар'!$C$14:$F$14,1))) -> 5850000 | S36: =IF(N36="","",((N36+IF(P36="",$D$3,P36))*$A$3+$F$3+R36)*(1+$H$3)) -> 20017767 | T36: =IF(O36="","",((O36+IF(P36="",$D$3,P36))*$A$3+$F$3+R36)*(1+$H$3)) -> 21368459 | U36: 26903000 | V36: 25796000 | W36: 27973000 | X36: =IF(OR(U36="",S36=""),"",U36-S36) -> 6885233 | Y36: =IF(X36="","",X36/S36) -> 0.3439561 | Z36: =IF(OR(U36="",T36=""),"",U36-T36) -> 5534541.3 | AA36: Найдвартай (40 зар) | AB36: гүйлт 107k +1.1%, G +1.1%, өнгө +7.1%, оноо 3 -3.3% | AC36: 2026-10-05 | AE36: Honda Kansai|70032|2026/10/05
A37: 2026/10/05 10:40 | B37: Honda Kansai | C37: 70012 | D37: Prius Alpha | E37: ZVW41W | F37: S TOURING SELECTION | G37: 2012 | H37: 100000 | I37: 1800 | J37: Хайбрид | K37: R | L37: хар | M37: Car Problem | N37: 275000 | Q37: =$L$3-G37 -> 14 | R37: =IF(J37="Хайбрид",INDEX('Онцгой татвар'!$C$6:$F$10,MATCH(I37,'Онцгой татвар'!$B$6:$B$10,1),MATCH(Q37,'Онцгой татвар'!$C$5:$F$5,1)),INDEX('Онцгой татвар'!$C$15:$F$19,MATCH(I37,'Онцгой татвар'!$B$15:$B$19,1),MATCH(Q37,'Онцгой татвар'!$C$14:$F$14,1))) -> 5850000 | S37: =IF(N37="","",((N37+IF(P37="",$D$3,P37))*$A$3+$F$3+R37)*(1+$H$3)) -> 19885346 | T37: =IF(O37="","",((O37+IF(P37="",$D$3,P37))*$A$3+$F$3+R37)*(1+$H$3)) | U37: 25763000 | V37: 24704000 | W37: 26788000 | X37: =IF(OR(U37="",S37=""),"",U37-S37) -> 5877653.8 | Y37: =IF(X37="","",X37/S37) -> 0.29557714 | Z37: =IF(OR(U37="",T37=""),"",U37-T37) | AA37: Найдвартай (47 зар) | AB37: гүйлт 100k +1.1%, S Touring +4.0% | AC37: 2026-10-05 | AE37: Honda Kansai|70012|2026/10/05
A38: 2026/10/05 09:32 | B38: Honda Kyushu | C38: 60009 | D38: Prius Alpha | E38: ZVW41W | F38: S TUNE BLACK | G38: 2013 | H38: 152000 | I38: 1800 | J38: Хайбрид | K38: 3.5 | L38: сувдан цагаан | M38: Аваагүй (өөр хүнд) | N38: 285000 | O38: 442000 | Q38: =$L$3-G38 -> 13 | R38: =IF(J38="Хайбрид",INDEX('Онцгой татвар'!$C$6:$F$10,MATCH(I38,'Онцгой татвар'!$B$6:$B$10,1),MATCH(Q38,'Онцгой татвар'!$C$5:$F$5,1)),INDEX('Онцгой татвар'!$C$15:$F$19,MATCH(I38,'Онцгой татвар'!$B$15:$B$19,1),MATCH(Q38,'Онцгой татвар'!$C$14:$F$14,1))) -> 5850000 | S38: =IF(N38="","",((N38+IF(P38="",$D$3,P38))*$A$3+$F$3+R38)*(1+$H$3)) -> 20150188 | T38: =IF(O38="","",((O38+IF(P38="",$D$3,P38))*$A$3+$F$3+R38)*(1+$H$3)) -> 24308199 | U38: 26812000 | V38: 25709000 | W38: 27879000 | X38: =IF(OR(U38="",S38=""),"",U38-S38) -> 6661812.2 | Y38: =IF(X38="","",X38/S38) -> 0.33060795 | Z38: =IF(OR(U38="",T38=""),"",U38-T38) -> 2503800.7 | AA38: Найдвартай (40 зар) | AB38: гүйлт 152k -0.1%, S Tune Black +0.8%, өнгө +6.1%, оноо 3.5 -1.2% | AC38: 2026-10-05 | AE38: Honda Kyushu|60009|2026/10/05

Sheet Аваагүй машинууд
A1: Авч чадаагүй машинууд: өөр хүнд зарагдсан үнээр авсан бол
A2: Бүх тоо 'Бүх машин' sheet-ээс томьёогоор ирнэ (ханш, ачилтын шар нүдийг тэнд засна). Зөрүү = зарагдсан үнэ − миний үнэ. Ашиг = загварын үнэ − зарагдсан үнээр буух үнэ.
A4: Хаагдах цаг | B4: Аукцион | C4: Лот | D4: Загвар | E4: Комплектац | F4: Он | G4: Гүйлт, км | H4: Оноо | I4: Өнгө | J4: Миний үнэ, ¥ | K4: Зарагдсан үнэ, ¥ | L4: Зөрүү, ¥ | M4: Зөрүү, % | N4: Буух үнэ (миний үнээр), ₮ | O4: Буух үнэ (зарагдсан үнээр), ₮ | P4: Монголд зарагдах үнэ (загвар), ₮ | Q4: Ашиг (зарагдсан үнээр), ₮ | R4: Ашгийн хувь (зарагдсан үнээр) | S4: Ашиг (миний үнээр), ₮ | T4: Загварын итгэл
A5: =IF('Бүх машин'!A16="","",'Бүх машин'!A16) -> 2026/10/06 12:38 | B5: =IF('Бүх машин'!B16="","",'Бүх машин'!B16) -> TAA Kinki | C5: =IF('Бүх машин'!C16="","",'Бүх машин'!C16) -> 70060 | D5: =IF('Бүх машин'!D16="","",'Бүх машин'!D16) -> Camry | E5: =IF('Бүх машин'!F16="","",'Бүх машин'!F16) -> G | F5: =IF('Бүх машин'!G16="","",'Бүх машин'!G16) -> 2017 | G5: =IF('Бүх машин'!H16="","",'Бүх машин'!H16) -> 111000 | H5: =IF('Бүх машин'!K16="","",'Бүх машин'!K16) -> 3.5 | I5: =IF('Бүх машин'!L16="","",'Бүх машин'!L16) -> сувдан цагаан | J5: =IF('Бүх машин'!N16="","",'Бүх машин'!N16) -> 980000 | K5: =IF('Бүх машин'!O16="","",'Бүх машин'!O16) -> 1294000 | L5: =K5-J5 -> 314000 | M5: =L5/J5 -> 0.32040816 | N5: =IF('Бүх машин'!S16="","",'Бүх машин'!S16) -> 34687422 | O5: =IF('Бүх машин'!T16="","",'Бүх машин'!T16) -> 43003445 | P5: =IF('Бүх машин'!U16="","",'Бүх машин'!U16) -> 46298000 | Q5: =IF('Бүх машин'!Z16="","",'Бүх машин'!Z16) -> 3294554.9 | R5: =IF(Q5="","",Q5/O5) -> 0.076611418 | S5: =IF('Бүх машин'!X16="","",'Бүх машин'!X16) -> 11610578 | T5: =IF('Бүх машин'!AA16="","",'Бүх машин'!AA16) -> Дунд (15 зар)
A6: =IF('Бүх машин'!A17="","",'Бүх машин'!A17) -> 2026/10/06 12:21 | B6: =IF('Бүх машин'!B17="","",'Бүх машин'!B17) -> TAA Kinki | C6: =IF('Бүх машин'!C17="","",'Бүх машин'!C17) -> 665 | D6: =IF('Бүх машин'!D17="","",'Бүх машин'!D17) -> Prius Alpha | E6: =IF('Бүх машин'!F17="","",'Бүх машин'!F17) -> S TOURING SELECTION | F6: =IF('Бүх машин'!G17="","",'Бүх машин'!G17) -> 2014 | G6: =IF('Бүх машин'!H17="","",'Бүх машин'!H17) -> 165000 | H6: =IF('Бүх машин'!K17="","",'Бүх машин'!K17) -> 3.5 | I6: =IF('Бүх машин'!L17="","",'Бүх машин'!L17) -> саарал | J6: =IF('Бүх машин'!N17="","",'Бүх машин'!N17) -> 275000 | K6: =IF('Бүх машин'!O17="","",'Бүх машин'!O17) -> 473000 | L6: =K6-J6 -> 198000 | M6: =L6/J6 -> 0.72 | N6: =IF('Бүх машин'!S17="","",'Бүх машин'!S17) -> 19885346 | O6: =IF('Бүх машин'!T17="","",'Бүх машин'!T17) -> 25129208 | P6: =IF('Бүх машин'!U17="","",'Бүх машин'!U17) -> 28624000 | Q6: =IF('Бүх машин'!Z17="","",'Бүх машин'!Z17) -> 3494792 | R6: =IF(Q6="","",Q6/O6) -> 0.13907291 | S6: =IF('Бүх машин'!X17="","",'Бүх машин'!X17) -> 8738653.8 | T6: =IF('Бүх машин'!AA17="","",'Бүх машин'!AA17) -> Дунд (17 зар)
A7: =IF('Бүх машин'!A18="","",'Бүх машин'!A18) -> 2026/10/06 12:07 | B7: =IF('Бүх машин'!B18="","",'Бүх машин'!B18) -> TAA Kinki | C7: =IF('Бүх машин'!C18="","",'Бүх машин'!C18) -> 620 | D7: =IF('Бүх машин'!D18="","",'Бүх машин'!D18) -> Prius Alpha | E7: =IF('Бүх машин'!F18="","",'Бүх машин'!F18) -> S TUNE BLACK | F7: =IF('Бүх машин'!G18="","",'Бүх машин'!G18) -> 2014 | G7: =IF('Бүх машин'!H18="","",'Бүх машин'!H18) -> 156000 | H7: =IF('Бүх машин'!K18="","",'Бүх машин'!K18) -> RA | I7: =IF('Бүх машин'!L18="","",'Бүх машин'!L18) -> хар | J7: =IF('Бүх машин'!N18="","",'Бүх машин'!N18) -> 280000 | K7: =IF('Бүх машин'!O18="","",'Бүх машин'!O18) -> 409000 | L7: =K7-J7 -> 129000 | M7: =L7/J7 -> 0.46071429 | N7: =IF('Бүх машин'!S18="","",'Бүх машин'!S18) -> 20017767 | O7: =IF('Бүх машин'!T18="","",'Бүх машин'!T18) -> 23434222 | P7: =IF('Бүх машин'!U18="","",'Бүх машин'!U18) -> 28687000 | Q7: =IF('Бүх машин'!Z18="","",'Бүх машин'!Z18) -> 5252777.7 | R7: =IF(Q7="","",Q7/O7) -> 0.22414986 | S7: =IF('Бүх машин'!X18="","",'Бүх машин'!X18) -> 8669233 | T7: =IF('Бүх машин'!AA18="","",'Бүх машин'!AA18) -> Дунд (17 зар)
A8: =IF('Бүх машин'!A19="","",'Бүх машин'!A19) -> 2026/10/06 11:44 | B8: =IF('Бүх машин'!B19="","",'Бүх машин'!B19) -> TAA Kyushu | C8: =IF('Бүх машин'!C19="","",'Бүх машин'!C19) -> 9048 | D8: =IF('Бүх машин'!D19="","",'Бүх машин'!D19) -> Prius Alpha | E8: =IF('Бүх машин'!F19="","",'Бүх машин'!F19) -> G | F8: =IF('Бүх машин'!G19="","",'Бүх машин'!G19) -> 2011 | G8: =IF('Бүх машин'!H19="","",'Бүх машин'!H19) -> 185000 | H8: =IF('Бүх машин'!K19="","",'Бүх машин'!K19) -> RA | I8: =IF('Бүх машин'!L19="","",'Бүх машин'!L19) -> сувдан цагаан | J8: =IF('Бүх машин'!N19="","",'Бүх машин'!N19) -> 275000 | K8: =IF('Бүх машин'!O19="","",'Бүх машин'!O19) -> 340000 | L8: =K8-J8 -> 65000 | M8: =L8/J8 -> 0.23636364 | N8: =IF('Бүх машин'!S19="","",'Бүх машин'!S19) -> 19885346 | O8: =IF('Бүх машин'!T19="","",'Бүх машин'!T19) -> 21606816 | P8: =IF('Бүх машин'!U19="","",'Бүх машин'!U19) -> 27087000 | Q8: =IF('Бүх машин'!Z19="","",'Бүх машин'!Z19) -> 5480184 | R8: =IF(Q8="","",Q8/O8) -> 0.25363219 | S8: =IF('Бүх машин'!X19="","",'Бүх машин'!X19) -> 7201653.8 | T8: =IF('Бүх машин'!AA19="","",'Бүх машин'!AA19) -> Дунд (18 зар)
A9: =IF('Бүх машин'!A20="","",'Бүх машин'!A20) -> 2026/10/06 11:00 | B9: =IF('Бүх машин'!B20="","",'Бүх машин'!B20) -> TAA Kyushu | C9: =IF('Бүх машин'!C20="","",'Бүх машин'!C20) -> 6130 | D9: =IF('Бүх машин'!D20="","",'Бүх машин'!D20) -> Camry | E9: =IF('Бүх машин'!F20="","",'Бүх машин'!F20) -> WS | F9: =IF('Бүх машин'!G20="","",'Бүх машин'!G20) -> 2018 | G9: =IF('Бүх машин'!H20="","",'Бүх машин'!H20) -> 145000 | H9: =IF('Бүх машин'!K20="","",'Бүх машин'!K20) -> 4 | I9: =IF('Бүх машин'!L20="","",'Бүх машин'!L20) -> сувдан цагаан | J9: =IF('Бүх машин'!N20="","",'Бүх машин'!N20) -> 1000000 | K9: =IF('Бүх машин'!O20="","",'Бүх машин'!O20) -> 1462000 | L9: =K9-J9 -> 462000 | M9: =L9/J9 -> 0.462 | N9: =IF('Бүх машин'!S20="","",'Бүх машин'!S20) -> 35217105 | O9: =IF('Бүх машин'!T20="","",'Бүх машин'!T20) -> 47452782 | P9: =IF('Бүх машин'!U20="","",'Бүх машин'!U20) -> 54293000 | Q9: =IF('Бүх машин'!Z20="","",'Бүх машин'!Z20) -> 6840217.7 | R9: =IF(Q9="","",Q9/O9) -> 0.14414787 | S9: =IF('Бүх машин'!X20="","",'Бүх машин'!X20) -> 19075895 | T9: =IF('Бүх машин'!AA20="","",'Бүх машин'!AA20) -> Өгөгдөл цөөн (8 зар)
A10: =IF('Бүх машин'!A21="","",'Бүх машин'!A21) -> 2026/10/06 10:57 | B10: =IF('Бүх машин'!B21="","",'Бүх машин'!B21) -> TAA Kinki | C10: =IF('Бүх машин'!C21="","",'Бүх машин'!C21) -> 387 | D10: =IF('Бүх машин'!D21="","",'Бүх машин'!D21) -> Prius | E10: =IF('Бүх машин'!F21="","",'Бүх машин'!F21) -> A | F10: =IF('Бүх машин'!G21="","",'Бүх машин'!G21) -> 2017 | G10: =IF('Бүх машин'!H21="","",'Бүх машин'!H21) -> 136000 | H10: =IF('Бүх машин'!K21="","",'Бүх машин'!K21) -> RA | I10: =IF('Бүх машин'!L21="","",'Бүх машин'!L21) -> мөнгөлөг | J10: =IF('Бүх машин'!N21="","",'Бүх машин'!N21) -> 660000 | K10: =IF('Бүх машин'!O21="","",'Бүх машин'!O21) -> 667000 | L10: =K10-J10 -> 7000 | M10: =L10/J10 -> 0.010606061 | N10: =IF('Бүх машин'!S21="","",'Бүх машин'!S21) -> 26212494 | O10: =IF('Бүх машин'!T21="","",'Бүх машин'!T21) -> 26397883 | P10: =IF('Бүх машин'!U21="","",'Бүх машин'!U21) -> 34277000 | Q10: =IF('Бүх машин'!Z21="","",'Бүх машин'!Z21) -> 7879117 | R10: =IF(Q10="","",Q10/O10) -> 0.29847533 | S10: =IF('Бүх машин'!X21="","",'Бүх машин'!X21) -> 8064506 | T10: =IF('Бүх машин'!AA21="","",'Бүх машин'!AA21) -> Найдвартай (32 зар)
A11: =IF('Бүх машин'!A22="","",'Бүх машин'!A22) -> 2026/10/06 10:40 | B11: =IF('Бүх машин'!B22="","",'Бүх машин'!B22) -> CAA Gifu | C11: =IF('Бүх машин'!C22="","",'Бүх машин'!C22) -> 30167 | D11: =IF('Бүх машин'!D22="","",'Бүх машин'!D22) -> Prius Alpha | E11: =IF('Бүх машин'!F22="","",'Бүх машин'!F22) -> G | F11: =IF('Бүх машин'!G22="","",'Бүх машин'!G22) -> 2011 | G11: =IF('Бүх машин'!H22="","",'Бүх машин'!H22) -> 149000 | H11: =IF('Бүх машин'!K22="","",'Бүх машин'!K22) -> 3.5 | I11: =IF('Бүх машин'!L22="","",'Бүх машин'!L22) -> сувдан цагаан | J11: =IF('Бүх машин'!N22="","",'Бүх машин'!N22) -> 305000 | K11: =IF('Бүх машин'!O22="","",'Бүх машин'!O22) -> 423000 | L11: =K11-J11 -> 118000 | M11: =L11/J11 -> 0.38688525 | N11: =IF('Бүх машин'!S22="","",'Бүх машин'!S22) -> 20679871 | O11: =IF('Бүх машин'!T22="","",'Бүх машин'!T22) -> 23805000 | P11: =IF('Бүх машин'!U22="","",'Бүх машин'!U22) -> 26983000 | Q11: =IF('Бүх машин'!Z22="","",'Бүх машин'!Z22) -> 3177999.5 | R11: =IF(Q11="","",Q11/O11) -> 0.13350134 | S11: =IF('Бүх машин'!X22="","",'Бүх машин'!X22) -> 6303129.2 | T11: =IF('Бүх машин'!AA22="","",'Бүх машин'!AA22) -> Дунд (18 зар)
A12: =IF('Бүх машин'!A23="","",'Бүх машин'!A23) -> 2026/10/06 10:19 | B12: =IF('Бүх машин'!B23="","",'Бүх машин'!B23) -> CAA Tokyo | C12: =IF('Бүх машин'!C23="","",'Бүх машин'!C23) -> 30044 | D12: =IF('Бүх машин'!D23="","",'Бүх машин'!D23) -> Prius | E12: =IF('Бүх машин'!F23="","",'Бүх машин'!F23) -> S TOURING SELECTION | F12: =IF('Бүх машин'!G23="","",'Бүх машин'!G23) -> 2018 | G12: =IF('Бүх машин'!H23="","",'Бүх машин'!H23) -> 205000 | H12: =IF('Бүх машин'!K23="","",'Бүх машин'!K23) -> 3.5 | I12: =IF('Бүх машин'!L23="","",'Бүх машин'!L23) -> сувдан цагаан | J12: =IF('Бүх машин'!N23="","",'Бүх машин'!N23) -> 500000 | K12: =IF('Бүх машин'!O23="","",'Бүх машин'!O23) -> 685000 | L12: =K12-J12 -> 185000 | M12: =L12/J12 -> 0.37 | N12: =IF('Бүх машин'!S23="","",'Бүх машин'!S23) -> 21975030 | O12: =IF('Бүх машин'!T23="","",'Бүх машин'!T23) -> 26874598 | P12: =IF('Бүх машин'!U23="","",'Бүх машин'!U23) -> 32969000 | Q12: =IF('Бүх машин'!Z23="","",'Бүх машин'!Z23) -> 6094402.2 | R12: =IF(Q12="","",Q12/O12) -> 0.22677185 | S12: =IF('Бүх машин'!X23="","",'Бүх машин'!X23) -> 10993970 | T12: =IF('Бүх машин'!AA23="","",'Бүх машин'!AA23) -> Өгөгдөл цөөн (7 зар)
A13: =IF('Бүх машин'!A24="","",'Бүх машин'!A24) -> 2026/10/06 10:11 | B13: =IF('Бүх машин'!B24="","",'Бүх машин'!B24) -> CAA Tokyo | C13: =IF('Бүх машин'!C24="","",'Бүх машин'!C24) -> 10318 | D13: =IF('Бүх машин'!D24="","",'Бүх машин'!D24) -> Prius Alpha | E13: =IF('Бүх машин'!F24="","",'Бүх машин'!F24) -> S TOURING SELECTION | F13: =IF('Бүх машин'!G24="","",'Бүх машин'!G24) -> 2012 | G13: =IF('Бүх машин'!H24="","",'Бүх машин'!H24) -> 161000 | H13: =IF('Бүх машин'!K24="","",'Бүх машин'!K24) -> 3.5 | I13: =IF('Бүх машин'!L24="","",'Бүх машин'!L24) -> сувдан цагаан | J13: =IF('Бүх машин'!N24="","",'Бүх машин'!N24) -> 295000 | K13: =IF('Бүх машин'!O24="","",'Бүх машин'!O24) -> 426000 | L13: =K13-J13 -> 131000 | M13: =L13/J13 -> 0.4440678 | N13: =IF('Бүх машин'!S24="","",'Бүх машин'!S24) -> 20415029 | O13: =IF('Бүх машин'!T24="","",'Бүх машин'!T24) -> 23884453 | P13: =IF('Бүх машин'!U24="","",'Бүх машин'!U24) -> 26634000 | Q13: =IF('Бүх машин'!Z24="","",'Бүх машин'!Z24) -> 2749547.1 | R13: =IF(Q13="","",Q13/O13) -> 0.1151187 | S13: =IF('Бүх машин'!X24="","",'Бүх машин'!X24) -> 6218970.8 | T13: =IF('Бүх машин'!AA24="","",'Бүх машин'!AA24) -> Найдвартай (47 зар)
A14: =IF('Бүх машин'!A25="","",'Бүх машин'!A25) -> 2026/10/06 09:54 | B14: =IF('Бүх машин'!B25="","",'Бүх машин'!B25) -> TAA Kinki | C14: =IF('Бүх машин'!C25="","",'Бүх машин'!C25) -> 180 | D14: =IF('Бүх машин'!D25="","",'Бүх машин'!D25) -> Prius Alpha | E14: =IF('Бүх машин'!F25="","",'Бүх машин'!F25) -> G | F14: =IF('Бүх машин'!G25="","",'Бүх машин'!G25) -> 2012 | G14: =IF('Бүх машин'!H25="","",'Бүх машин'!H25) -> 160000 | H14: =IF('Бүх машин'!K25="","",'Бүх машин'!K25) -> 3.5 | I14: =IF('Бүх машин'!L25="","",'Бүх машин'!L25) -> мөнгөлөг | J14: =IF('Бүх машин'!N25="","",'Бүх машин'!N25) -> 270000 | K14: =IF('Бүх машин'!O25="","",'Бүх машин'!O25) -> 334000 | L14: =K14-J14 -> 64000 | M14: =L14/J14 -> 0.23703704 | N14: =IF('Бүх машин'!S25="","",'Бүх машин'!S25) -> 19752926 | O14: =IF('Бүх машин'!T25="","",'Бүх машин'!T25) -> 21447911 | P14: =IF('Бүх машин'!U25="","",'Бүх машин'!U25) -> 26164000 | Q14: =IF('Бүх машин'!Z25="","",'Бүх машин'!Z25) -> 4716088.9 | R14: =IF(Q14="","",Q14/O14) -> 0.2198857 | S14: =IF('Бүх машин'!X25="","",'Бүх машин'!X25) -> 6411074.5 | T14: =IF('Бүх машин'!AA25="","",'Бүх машин'!AA25) -> Найдвартай (47 зар)
A15: =IF('Бүх машин'!A26="","",'Бүх машин'!A26) -> 2026/10/06 09:50 | B15: =IF('Бүх машин'!B26="","",'Бүх машин'!B26) -> TAA Hiroshima | C15: =IF('Бүх машин'!C26="","",'Бүх машин'!C26) -> 174 | D15: =IF('Бүх машин'!D26="","",'Бүх машин'!D26) -> Prius | E15: =IF('Бүх машин'!F26="","",'Бүх машин'!F26) -> A PREMIUM | F15: =IF('Бүх машин'!G26="","",'Бүх машин'!G26) -> 2017 | G15: =IF('Бүх машин'!H26="","",'Бүх машин'!H26) -> 189000 | H15: =IF('Бүх машин'!K26="","",'Бүх машин'!K26) -> 3.5 | I15: =IF('Бүх машин'!L26="","",'Бүх машин'!L26) -> цагаан | J15: =IF('Бүх машин'!N26="","",'Бүх машин'!N26) -> 530000 | K15: =IF('Бүх машин'!O26="","",'Бүх машин'!O26) -> 687000 | L15: =K15-J15 -> 157000 | M15: =L15/J15 -> 0.29622642 | N15: =IF('Бүх машин'!S26="","",'Бүх машин'!S26) -> 22769554 | O15: =IF('Бүх машин'!T26="","",'Бүх машин'!T26) -> 26927566 | P15: =IF('Бүх машин'!U26="","",'Бүх машин'!U26) -> 34406000 | Q15: =IF('Бүх машин'!Z26="","",'Бүх машин'!Z26) -> 7478434 | R15: =IF(Q15="","",Q15/O15) -> 0.2777241 | S15: =IF('Бүх машин'!X26="","",'Бүх машин'!X26) -> 11636446 | T15: =IF('Бүх машин'!AA26="","",'Бүх машин'!AA26) -> Найдвартай (32 зар)
A16: =IF('Бүх машин'!A27="","",'Бүх машин'!A27) -> 2026/10/06 09:37 | B16: =IF('Бүх машин'!B27="","",'Бүх машин'!B27) -> CAA Tokyo | C16: =IF('Бүх машин'!C27="","",'Бүх машин'!C27) -> 10170 | D16: =IF('Бүх машин'!D27="","",'Бүх машин'!D27) -> Prius Alpha | E16: =IF('Бүх машин'!F27="","",'Бүх машин'!F27) -> G TOURING SELECTION | F16: =IF('Бүх машин'!G27="","",'Бүх машин'!G27) -> 2012 | G16: =IF('Бүх машин'!H27="","",'Бүх машин'!H27) -> 169000 | H16: =IF('Бүх машин'!K27="","",'Бүх машин'!K27) -> 3.5 | I16: =IF('Бүх машин'!L27="","",'Бүх машин'!L27) -> сувдан цагаан | J16: =IF('Бүх машин'!N27="","",'Бүх машин'!N27) -> 295000 | K16: =IF('Бүх машин'!O27="","",'Бүх машин'!O27) -> 429000 | L16: =K16-J16 -> 134000 | M16: =L16/J16 -> 0.45423729 | N16: =IF('Бүх машин'!S27="","",'Бүх машин'!S27) -> 20415029 | O16: =IF('Бүх машин'!T27="","",'Бүх машин'!T27) -> 23963905 | P16: =IF('Бүх машин'!U27="","",'Бүх машин'!U27) -> 26387000 | Q16: =IF('Бүх машин'!Z27="","",'Бүх машин'!Z27) -> 2423094.6 | R16: =IF(Q16="","",Q16/O16) -> 0.10111435 | S16: =IF('Бүх машин'!X27="","",'Бүх машин'!X27) -> 5971970.8 | T16: =IF('Бүх машин'!AA27="","",'Бүх машин'!AA27) -> Найдвартай (47 зар)
... A18: =IF('Бүх машин'!A29="","",'Бүх машин'!A29) -> 2026/10/05 14:40 | B18: =IF('Бүх машин'!B29="","",'Бүх машин'!B29) -> Honda Nagoya | C18: =IF('Бүх машин'!C29="","",'Бүх машин'!C29) -> 55383 | D18: =IF('Бүх машин'!D29="","",'Бүх машин'!D29) -> Prius Alpha | E18: =IF('Бүх машин'!F29="","",'Бүх машин'!F29) -> G | F18: =IF('Бүх машин'!G29="","",'Бүх машин'!G29) -> 2014 | G18: =IF('Бүх машин'!H29="","",'Бүх машин'!H29) -> 98000 | H18: =IF('Бүх машин'!K29="","",'Бүх машин'!K29) -> R | I18: =IF('Бүх машин'!L29="","",'Бүх машин'!L29) -> мөнгөлөг | J18: =IF('Бүх машин'!N29="","",'Бүх машин'!N29) -> 300000 | K18: =IF('Бүх машин'!O29="","",'Бүх машин'!O29) -> 423000 | L18: =K18-J18 -> 123000 | M18: =L18/J18 -> 0.41 | N18: =IF('Бүх машин'!S29="","",'Бүх машин'!S29) -> 20547450 | O18: =IF('Бүх машин'!T29="","",'Бүх машин'!T29) -> 23805000 | P18: =IF('Бүх машин'!U29="","",'Бүх машин'!U29) -> 30251000 | Q18: =IF('Бүх машин'!Z29="","",'Бүх машин'!Z29) -> 6445999.5 | R18: =IF(Q18="","",Q18/O18) -> 0.27078342 | S18: =IF('Бүх машин'!X29="","",'Бүх машин'!X29) -> 9703550 | T18: =IF('Бүх машин'!AA29="","",'Бүх машин'!AA29) -> Дунд (17 зар)
A19: =IF('Бүх машин'!A31="","",'Бүх машин'!A31) -> 2026/10/05 13:47 | B19: =IF('Бүх машин'!B31="","",'Бүх машин'!B31) -> Honda Tokyo | C19: =IF('Бүх машин'!C31="","",'Бүх машин'!C31) -> 20287 | D19: =IF('Бүх машин'!D31="","",'Бүх машин'!D31) -> Prius Alpha | E19: =IF('Бүх машин'!F31="","",'Бүх машин'!F31) -> S TUNE BLACK | F19: =IF('Бүх машин'!G31="","",'Бүх машин'!G31) -> 2014 | G19: =IF('Бүх машин'!H31="","",'Бүх машин'!H31) -> 140000 | H19: =IF('Бүх машин'!K31="","",'Бүх машин'!K31) -> R | I19: =IF('Бүх машин'!L31="","",'Бүх машин'!L31) -> хар | J19: =IF('Бүх машин'!N31="","",'Бүх машин'!N31) -> 220000 | K19: =IF('Бүх машин'!O31="","",'Бүх машин'!O31) -> 311000 | L19: =K19-J19 -> 91000 | M19: =L19/J19 -> 0.41363636 | N19: =IF('Бүх машин'!S31="","",'Бүх машин'!S31) -> 18428718 | O19: =IF('Бүх машин'!T31="","",'Бүх машин'!T31) -> 20838776 | P19: =IF('Бүх машин'!U31="","",'Бүх машин'!U31) -> 27823000 | Q19: =IF('Бүх машин'!Z31="","",'Бүх машин'!Z31) -> 6984224.3 | R19: =IF(Q19="","",Q19/O19) -> 0.33515522 | S19: =IF('Бүх машин'!X31="","",'Бүх машин'!X31) -> 9394282 | T19: =IF('Бүх машин'!AA31="","",'Бүх машин'!AA31) -> Дунд (17 зар)
A20: =IF('Бүх машин'!A32="","",'Бүх машин'!A32) -> 2026/10/05 12:29 | B20: =IF('Бүх машин'!B32="","",'Бүх машин'!B32) -> Honda Sendai | C20: =IF('Бүх машин'!C32="","",'Бүх машин'!C32) -> 40063 | D20: =IF('Бүх машин'!D32="","",'Бүх машин'!D32) -> Prius Alpha | E20: =IF('Бүх машин'!F32="","",'Бүх машин'!F32) -> S TUNE BLACK | F20: =IF('Бүх машин'!G32="","",'Бүх машин'!G32) -> 2013 | G20: =IF('Бүх машин'!H32="","",'Бүх машин'!H32) -> 163000 | H20: =IF('Бүх машин'!K32="","",'Бүх машин'!K32) -> 3.5 | I20: =IF('Бүх машин'!L32="","",'Бүх машин'!L32) -> сувдан цагаан | J20: =IF('Бүх машин'!N32="","",'Бүх машин'!N32) -> 285000 | K20: =IF('Бүх машин'!O32="","",'Бүх машин'!O32) -> 365000 | L20: =K20-J20 -> 80000 | M20: =L20/J20 -> 0.28070175 | N20: =IF('Бүх машин'!S32="","",'Бүх машин'!S32) -> 20150188 | O20: =IF('Бүх машин'!T32="","",'Бүх машин'!T32) -> 22268920 | P20: =IF('Бүх машин'!U32="","",'Бүх машин'!U32) -> 26726000 | Q20: =IF('Бүх машин'!Z32="","",'Бүх машин'!Z32) -> 4457080.2 | R20: =IF(Q20="","",Q20/O20) -> 0.20014802 | S20: =IF('Бүх машин'!X32="","",'Бүх машин'!X32) -> 6575812.2 | T20: =IF('Бүх машин'!AA32="","",'Бүх машин'!AA32) -> Найдвартай (40 зар)
A21: =IF('Бүх машин'!A33="","",'Бүх машин'!A33) -> 2026/10/05 11:47 | B21: =IF('Бүх машин'!B33="","",'Бүх машин'!B33) -> JU Tokyo | C21: =IF('Бүх машин'!C33="","",'Бүх машин'!C33) -> 7045 | D21: =IF('Бүх машин'!D33="","",'Бүх машин'!D33) -> Prius Alpha | E21: =IF('Бүх машин'!F33="","",'Бүх машин'!F33) -> G TOURING SELECTION | F21: =IF('Бүх машин'!G33="","",'Бүх машин'!G33) -> 2014 | G21: =IF('Бүх машин'!H33="","",'Бүх машин'!H33) -> 119000 | H21: =IF('Бүх машин'!K33="","",'Бүх машин'!K33) -> 3.5 | I21: =IF('Бүх машин'!L33="","",'Бүх машин'!L33) -> хар | J21: =IF('Бүх машин'!N33="","",'Бүх машин'!N33) -> 280000 | K21: =IF('Бүх машин'!O33="","",'Бүх машин'!O33) -> 450000 | L21: =K21-J21 -> 170000 | M21: =L21/J21 -> 0.60714286 | N21: =IF('Бүх машин'!S33="","",'Бүх машин'!S33) -> 20017767 | O21: =IF('Бүх машин'!T33="","",'Бүх машин'!T33) -> 24520072 | P21: =IF('Бүх машин'!U33="","",'Бүх машин'!U33) -> 28311000 | Q21: =IF('Бүх машин'!Z33="","",'Бүх машин'!Z33) -> 3790927.5 | R21: =IF(Q21="","",Q21/O21) -> 0.15460507 | S21: =IF('Бүх машин'!X33="","",'Бүх машин'!X33) -> 8293233 | T21: =IF('Бүх машин'!AA33="","",'Бүх машин'!AA33) -> Дунд (17 зар)
A22: =IF('Бүх машин'!A34="","",'Бүх машин'!A34) -> 2026/10/05 11:34 | B22: =IF('Бүх машин'!B34="","",'Бүх машин'!B34) -> Honda Nagoya | C22: =IF('Бүх машин'!C34="","",'Бүх машин'!C34) -> 55070 | D22: =IF('Бүх машин'!D34="","",'Бүх машин'!D34) -> Prius Alpha | E22: =IF('Бүх машин'!F34="","",'Бүх машин'!F34) -> S | F22: =IF('Бүх машин'!G34="","",'Бүх машин'!G34) -> 2012 | G22: =IF('Бүх машин'!H34="","",'Бүх машин'!H34) -> 100000 | H22: =IF('Бүх машин'!K34="","",'Бүх машин'!K34) -> 4 | I22: =IF('Бүх машин'!L34="","",'Бүх машин'!L34) -> сувдан цагаан | J22: =IF('Бүх машин'!N34="","",'Бүх машин'!N34) -> 301000 | K22: =IF('Бүх машин'!O34="","",'Бүх машин'!O34) -> 443000 | L22: =K22-J22 -> 142000 | M22: =L22/J22 -> 0.4717608 | N22: =IF('Бүх машин'!S34="","",'Бүх машин'!S34) -> 20573934 | O22: =IF('Бүх машин'!T34="","",'Бүх машин'!T34) -> 24334683 | P22: =IF('Бүх машин'!U34="","",'Бүх машин'!U34) -> 26516000 | Q22: =IF('Бүх машин'!Z34="","",'Бүх машин'!Z34) -> 2181316.5 | R22: =IF(Q22="","",Q22/O22) -> 0.089638172 | S22: =IF('Бүх машин'!X34="","",'Бүх машин'!X34) -> 5942065.8 | T22: =IF('Бүх машин'!AA34="","",'Бүх машин'!AA34) -> Найдвартай (47 зар)
A23: =IF('Бүх машин'!A35="","",'Бүх машин'!A35) -> 2026/10/05 11:09 | B23: =IF('Бүх машин'!B35="","",'Бүх машин'!B35) -> Honda Tokyo | C23: =IF('Бүх машин'!C35="","",'Бүх машин'!C35) -> 20017 | D23: =IF('Бүх машин'!D35="","",'Бүх машин'!D35) -> Prius Alpha | E23: =IF('Бүх машин'!F35="","",'Бүх машин'!F35) -> S TOURING SELECTION | F23: =IF('Бүх машин'!G35="","",'Бүх машин'!G35) -> 2012 | G23: =IF('Бүх машин'!H35="","",'Бүх машин'!H35) -> 177000 | H23: =IF('Бүх машин'!K35="","",'Бүх машин'!K35) -> 3.5 | I23: =IF('Бүх машин'!L35="","",'Бүх машин'!L35) -> цагаан | J23: =IF('Бүх машин'!N35="","",'Бүх машин'!N35) -> 290000 | K23: =IF('Бүх машин'!O35="","",'Бүх машин'!O35) -> 410000 | L23: =K23-J23 -> 120000 | M23: =L23/J23 -> 0.4137931 | N23: =IF('Бүх машин'!S35="","",'Бүх машин'!S35) -> 20282608 | O23: =IF('Бүх машин'!T35="","",'Бүх машин'!T35) -> 23460706 | P23: =IF('Бүх машин'!U35="","",'Бүх машин'!U35) -> 25937000 | Q23: =IF('Бүх машин'!Z35="","",'Бүх машин'!Z35) -> 2476293.5 | R23: =IF(Q23="","",Q23/O23) -> 0.10555068 | S23: =IF('Бүх машин'!X35="","",'Бүх машин'!X35) -> 5654391.5 | T23: =IF('Бүх машин'!AA35="","",'Бүх машин'!AA35) -> Найдвартай (47 зар)
A24: =IF('Бүх машин'!A36="","",'Бүх машин'!A36) -> 2026/10/05 10:46 | B24: =IF('Бүх машин'!B36="","",'Бүх машин'!B36) -> Honda Kansai | C24: =IF('Бүх машин'!C36="","",'Бүх машин'!C36) -> 70032 | D24: =IF('Бүх машин'!D36="","",'Бүх машин'!D36) -> Prius Alpha | E24: =IF('Бүх машин'!F36="","",'Бүх машин'!F36) -> G | F24: =IF('Бүх машин'!G36="","",'Бүх машин'!G36) -> 2013 | G24: =IF('Бүх машин'!H36="","",'Бүх машин'!H36) -> 107000 | H24: =IF('Бүх машин'!K36="","",'Бүх машин'!K36) -> 3 | I24: =IF('Бүх машин'!L36="","",'Бүх машин'!L36) -> мөнгөлөг | J24: =IF('Бүх машин'!N36="","",'Бүх машин'!N36) -> 280000 | K24: =IF('Бүх машин'!O36="","",'Бүх машин'!O36) -> 331000 | L24: =K24-J24 -> 51000 | M24: =L24/J24 -> 0.18214286 | N24: =IF('Бүх машин'!S36="","",'Бүх машин'!S36) -> 20017767 | O24: =IF('Бүх машин'!T36="","",'Бүх машин'!T36) -> 21368459 | P24: =IF('Бүх машин'!U36="","",'Бүх машин'!U36) -> 26903000 | Q24: =IF('Бүх машин'!Z36="","",'Бүх машин'!Z36) -> 5534541.3 | R24: =IF(Q24="","",Q24/O24) -> 0.25900517 | S24: =IF('Бүх машин'!X36="","",'Бүх машин'!X36) -> 6885233 | T24: =IF('Бүх машин'!AA36="","",'Бүх машин'!AA36) -> Найдвартай (40 зар)
A25: =IF('Бүх машин'!A38="","",'Бүх машин'!A38) -> 2026/10/05 09:32 | B25: =IF('Бүх машин'!B38="","",'Бүх машин'!B38) -> Honda Kyushu | C25: =IF('Бүх машин'!C38="","",'Бүх машин'!C38) -> 60009 | D25: =IF('Бүх машин'!D38="","",'Бүх машин'!D38) -> Prius Alpha | E25: =IF('Бүх машин'!F38="","",'Бүх машин'!F38) -> S TUNE BLACK | F25: =IF('Бүх машин'!G38="","",'Бүх машин'!G38) -> 2013 | G25: =IF('Бүх машин'!H38="","",'Бүх машин'!H38) -> 152000 | H25: =IF('Бүх машин'!K38="","",'Бүх машин'!K38) -> 3.5 | I25: =IF('Бүх машин'!L38="","",'Бүх машин'!L38) -> сувдан цагаан | J25: =IF('Бүх машин'!N38="","",'Бүх машин'!N38) -> 285000 | K25: =IF('Бүх машин'!O38="","",'Бүх машин'!O38) -> 442000 | L25: =K25-J25 -> 157000 | M25: =L25/J25 -> 0.55087719 | N25: =IF('Бүх машин'!S38="","",'Бүх машин'!S38) -> 20150188 | O25: =IF('Бүх машин'!T38="","",'Бүх машин'!T38) -> 24308199 | P25: =IF('Бүх машин'!U38="","",'Бүх машин'!U38) -> 26812000 | Q25: =IF('Бүх машин'!Z38="","",'Бүх машин'!Z38) -> 2503800.7 | R25: =IF(Q25="","",Q25/O25) -> 0.10300231 | S25: =IF('Бүх машин'!X38="","",'Бүх машин'!X38) -> 6661812.2 | T25: =IF('Бүх машин'!AA38="","",'Бүх машин'!AA38) -> Найдвартай (40 зар)
A27: Дундаж (21 машин) | J27: =IFERROR(AVERAGE(J5:J25),"") -> 421714.29 | K27: =IFERROR(AVERAGE(K5:K25),"") -> 580238.1 | L27: =IFERROR(AVERAGE(L5:L25),"") -> 158523.81 | M27: =IFERROR(AVERAGE(M5:M25),"") -> 0.38963262 | O27: =IFERROR(AVERAGE(O5:O25),"") -> 26863818 | P27: =IFERROR(AVERAGE(P5:P25),"") -> 31689667 | Q27: =IFERROR(AVERAGE(Q5:Q25),"") -> 4825848.9 | R27: =IFERROR(AVERAGE(R5:R25),"") -> 0.18602831
A28: Өөр хүмүүс таны үнээс дунджаар 'Зөрүү, %'-иар илүү үнэ тавьж авсан. 'Ашгийн хувь (зарагдсан үнээр)' нь тэр үнээр авсан ч хэдэн хувийн ашиг үлдэхийг харуулна.

Sheet Онцгой татвар
A1: Суудлын автомашины импортын онцгой татвар, ₮ (засаж болно)
A3: 1. Хайбрид ба газ
A4: Хөдөлгүүр (cc) | B4: Доод хязгаар | C4: 0-3 жил | D4: 4-6 жил | E4: 7-9 жил | F4: 10-с дээш
B5: нас ≥ | C5: 0 | D5: 4 | E5: 7 | F5: 10
A6: 1-1500 | B6: 1 | C6: 375000 | D6: 800000 | E6: 1675000 | F6: 5000000
A7: 1501-2500 | B7: 1501 | C7: 1150000 | D7: 1600000 | E7: 2500000 | F7: 5850000
A8: 2501-3500 | B8: 2501 | C8: 1525000 | D8: 2000000 | E8: 3350000 | F8: 6675000
A9: 3501-4500 | B9: 3501 | C9: 3425375 | D9: 4000000 | E9: 5425000 | F9: 8750000
A10: 4501-с дээш | B10: 4501 | C10: 7105000 | D10: 13600000 | E10: 19575000 | F10: 32987500
A12: 2. Энгийн бензин, дизель
A13: Хөдөлгүүр (cc) | B13: Доод хязгаар | C13: 0-3 жил | D13: 4-6 жил | E13: 7-9 жил | F13: 10-с дээш
B14: нас ≥ | C14: 0 | D14: 4 | E14: 7 | F14: 10
A15: 1-1500 | B15: 1 | C15: 750000 | D15: 1600000 | E15: 3350000 | F15: 10000000
A16: 1501-2500 | B16: 1501 | C16: 2300000 | D16: 3200000 | E16: 5000000 | F16: 11700000
A17: 2501-3500 | B17: 2501 | C17: 3050000 | D17: 4000000 | E17: 6700000 | F17: 13350000
A18: 3501-4500 | B18: 3501 | C18: 6850750 | D18: 8000000 | E18: 10850000 | F18: 17500000
A19: 4501-с дээш | B19: 4501 | C19: 14210000 | D19: 27200000 | E19: 39150000 | F19: 65975000
A21: Суудлын автомашины импортын онцгой татвар, шинэ хувь хэмжээ. Нас = тооцох он - үйлдвэрлэсэн он.

Sheet Тайлбар
A1: Тооцоолол
A2: Буух үнэ = [(үнэ ¥ + нэмэх ¥) × иен ханш + ачилт + онцгой татвар] × (1 + НӨАТ). Шар нүдийг 'Бүх машин' sheet-ийн дээд хэсэгт засна.
A3: Буух үнэ (эцсийн үнээр): аукционы эцсийн үнээр авсан бол хэд болохыг харуулна (аваагүй машинд харьцуулалт).
A4: Монголд зарагдах үнэ: car-valuation үнэлгээний загвар (model_2026-10-04_v6_2026fresh.json) — unegui.mn-ийн 2026 онд орж ирсэн, дугаар аваагүй зарууд.
A5: Загварын үнэ нь зарын (асуусан) үнэ. Бодит зарагдах үнэ ихэвчлэн арай бага. Доод/Дээд = зарын 50% энэ хооронд.
A6: Аукционы оноо R/RA (засвартай) бол загварт оруулаагүй. Мөнгөлөг өнгө = 'бусад өнгө'.
A7: Ашигт гаалийн 5% албан татвар, бүртгэл, засвар, зуучлалын зардал ороогүй.
